Workbook

Sheet Traceability
A1: Review Master - User Story Traceability Matrix
A2: Each story mapped to backend module, architecture section, API endpoints, tables, agents/skills, delivery phase and test approach. All references were checked against openapi.yaml, DATA_MODEL.md, SKILLS.md and AGENTS.md at build time.
A4: Version | B4: Story ID | C4: Title | D4: Role | E4: Priority | F4: Status | G4: Phase | H4: Sprints | I4: Backend module(s) | J4: Architecture reference | K4: API endpoints | L4: Key tables | M4: Agents / skills | N4: Flow | O4: Test approach | P4: Notes / gaps
A5: V1 | B5: US-002 | C5: Resolve canonical product and variant | D5: Consumer | E5: Must Have | F5: Draft | G5: Phase 1 | H5: S2-S4 | I5: catalog | J5: Architecture §3.4; ADR-0006 | K5: POST /api/v1/products/identify | L5: product_families, listings, product_mappings, match_candidates, variants | M5: match_product, resolve_variant, Identity Matching Assistant | N5: SEQUENCE §1 | O5: Unit tests of matching order; labeled-set accuracy method (TEST_STRATEGY §4)
A6: V1 | B6: US-003 | C6: Correct product identification | D6: Consumer | E6: Must Have | F6: Draft | G6: Phase 1 | H6: S2-S4 | I6: catalog + admin | J6: Architecture §3.4 | K6: POST /api/v1/products/corrections | L6: product_corrections, audit_log | M6: - | N6: SEQUENCE §1 | O6: Integration: a user correction never changes the global mapping; audit row exists
A7: V1 | B7: US-004 | C7: View normalized specifications | D7: Consumer | E7: Must Have | F7: Draft | G7: Phase 1 | H7: S2-S4 | I7: normalization | J7: Architecture §3.5 | K7: GET /api/v1/variants/{variant_id} GET /api/v1/products/{product_id} | L7: categories, variants | M7: normalize_specs, convert_units | N7: - | O7: Unit + property tests (units, missing is null, conflicting sources shown)
A8: V1 | B8: US-005 | C8: Search products on the website | D8: Consumer | E8: Must Have | F8: Draft | G8: Phase 1 | H8: S2-S4 | I8: catalog | J8: DATA_MODEL §4 (pg_trgm search) | K8: GET /api/v1/products | L8: products | M8: - | N8: - | O8: Integration: search ranking, empty and misspelled queries
A9: V1 | B9: US-033 | C9: Manage users, roles, and permissions | D9: Admin | E9: Must Have | F9: Draft | G9: Phase 1 | H9: S2-S4 | I9: auth + admin | J9: Architecture §3.16; SECURITY §2 | K9: GET /api/v1/users/me GET /api/v1/admin/users PUT /api/v1/admin/users/{user_id}/roles | L9: users, memberships, audit_log | M9: check_permission, log_trace | N9: SEQUENCE §5 | O9: Escalation tests; role change audited; MFA for admin/expert | P9: Admin user/role endpoints added to the API skeleton
A10: V1 | B10: US-034 | C10: Manage categories and versioned evaluation models | D10: Admin | E10: Must Have | F10: Clarification Required | G10: Phase 1 | H10: S2-S4 | I10: evaluation + admin | J10: EVALUATION_MODEL_SPECS; ADR-0004 | K10: GET /api/v1/admin/evaluation-models GET /api/v1/admin/evaluation-models/{model_id} POST /api/v1/admin/evaluation-models/{model_id}/versions POST /api/v1/admin/evaluation-model-versions/{version_id}/publish | L10: evaluation_models, evaluation_model_versions, audit_log | M10: log_trace | N10: - | O10: Publish rejected if any weight/threshold is null or weights do not sum to 1.0; published version immutable | P10: Domain experts must supply weights and thresholds
A11: V1 | B11: US-035 | C11: Manage product mappings and ambiguous matches | D11: Admin | E11: Must Have | F11: Draft | G11: Phase 1 | H11: S2-S4 | I11: admin + catalog | J11: Architecture §3.4 | K11: GET /api/v1/admin/mappings/queue POST /api/v1/admin/mappings/{item_id}/resolve | L11: product_mappings, match_candidates, audit_log | M11: log_trace | N11: - | O11: Versioned mapping change; split reassigns evaluations correctly
A12: V1 | B12: US-036 | C12: Protect and manage evidence | D12: Admin | E12: Must Have | F12: Draft | G12: Phase 1 | H12: S2-S4 | I12: evidence + admin | J12: Architecture §3.6 | K12: POST /api/v1/evidence POST /api/v1/evidence/{evidence_id}/versions | L12: evidence, evidence_versions, evidence_documents | M12: check_upload_safety, attach_trust_tier | N12: SEQUENCE §2 | O12: Disguised executable rejected; replacing evidence keeps the old version
A13: V1 | B13: US-037 | C13: Audit log of material changes | D13: Admin | E13: Must Have | F13: Draft | G13: Phase 1 | H13: S2-S4 | I13: admin | J13: Architecture §3.17; DATA_MODEL §3 | K13: GET /api/v1/admin/audit-log | L13: audit_log, ai_runs | M13: log_trace | N13: - | O13: App role has INSERT only; failed actions also recorded
A14: V1 | B14: US-006 | C14: View product page with separated trust outputs | D14: Consumer | E14: Must Have | F14: Draft | G14: Phase 2 | H14: S4-S7 | I14: evaluation + community + expert (read) | J14: Architecture §3.1, §3.7; AGENTS §10 | K14: GET /api/v1/variants/{variant_id} | L14: evaluations, feedback, expert_assessments, offers | M14: Response Assembler | N14: SEQUENCE §1 | O14: Contract test: three outputs separate; no blended score field exists
A15: V1 | B15: US-008 | C15: Deterministic category-based evaluation | D15: Consumer | E15: Must Have | F15: Clarification Required | G15: Phase 2 | H15: S4-S7 | I15: evaluation | J15: Architecture §3.7; ADR-0003, ADR-0004; EVALUATION_MODEL_SPECS | K15: GET /api/v1/variants/{variant_id}/evaluation | L15: evaluation_model_versions, evaluations, parameter_results | M15: score_parameter, resolve_evidence_conflict, renormalize_weights, compute_confidence, aggregate_evaluation | N15: SEQUENCE §2 | O15: Golden determinism gate in CI; same score across extension/web/API | P15: Needs decision on `value` (ADR-0005) and approved models
A16: V1 | B16: US-009 | C16: View Review Master score and parameter scores | D16: Consumer | E16: Must Have | F16: Draft | G16: Phase 2 | H16: S4-S7 | I16: evaluation | J16: Architecture §3.7, §4 (cache) | K16: GET /api/v1/variants/{variant_id}/evaluation | L16: evaluations, parameter_results | M16: cache_lookup, compute_value_signal | N16: SEQUENCE §1 | O16: Performance test: cached retrieval about <= 2 s (NFR)
A17: V1 | B17: US-010 | C17: View confidence level separate from score | D17: Consumer | E17: Must Have | F17: Clarification Required | G17: Phase 2 | H17: S4-S7 | I17: evaluation | J17: Architecture §3.7 rules 6-10 | K17: GET /api/v1/variants/{variant_id}/evaluation | L17: evaluations | M17: compute_confidence, compute_freshness | N17: SEQUENCE §2 | O17: Golden fixtures: thin evidence, missing critical parameter, coverage floor | P17: Thresholds are heuristics to calibrate
A18: V1 | B18: US-011 | C18: Inspect evidence and its provenance | D18: Consumer | E18: Must Have | F18: Draft | G18: Phase 2 | H18: S4-S7 | I18: evidence | J18: Architecture §3.6 | K18: GET /api/v1/evidence/{evidence_id} GET /api/v1/evidence/{evidence_id}/versions | L18: evidence, evidence_versions, evidence_documents | M18: attach_trust_tier, classify_source_label | N18: SEQUENCE §2 | O18: Unit: a manufacturer source can never get an 'independent test' label; permission test on private evidence
A19: V1 | B19: US-013 | C19: View evaluation history | D19: Consumer | E19: Should Have | F19: Draft | G19: Phase 2 | H19: S4-S7 | I19: evaluation | J19: Architecture §3.7 (versioning); ADR-0004 | K19: GET /api/v1/variants/{variant_id}/evaluation/history | L19: evaluations | M19: - | N19: SEQUENCE §2 | O19: DB test: no UPDATE/DELETE on evaluations for the app role
A20: V1 | B20: US-001 | C20: Detect product on supported marketplace page | D20: Consumer | E20: Must Have | F20: Clarification Required | G20: Phase 3 | H20: S6-S10 | I20: Extension + catalog | J20: CLIENTS_EVENTS_RELIABILITY §1; Architecture §3.1, §3.4 | K20: POST /api/v1/products/identify | L20: listings, proposed_attributes | M20: match_product, Product Extraction Agent | N20: SEQUENCE §1 | O20: Playwright extension suite (supported/unsupported/API down/ambiguous); manifest permission gate in CI | P20: Blocked by decision #1 (V1 marketplace)
A21: V1 | B21: US-018 | C21: Compare products side by side | D21: Consumer | E21: Must Have | F21: Draft | G21: Phase 3 | H21: S6-S10 | I21: comparison | J21: Architecture §3.11 | K21: POST /api/v1/comparisons | L21: comparisons | M21: build_comparison_matrix | N21: - | O21: Cross-category blocked; insufficient-evidence product shown, not ranked as zero
A22: V1 | B22: US-020 | C22: Discover alternatives | D22: Consumer | E22: Must Have | F22: Draft | G22: Phase 3 | H22: S6-S10 | I22: comparison | J22: Architecture §3.11 | K22: GET /api/v1/variants/{variant_id}/alternatives | L22: variants, evaluations | M22: build_comparison_matrix | N22: - | O22: Eligible-only alternatives; low-confidence flagged
A23: V1 | B23: US-021 | C23: Enter requirements in natural language | D23: Consumer | E23: Must Have | F23: Draft | G23: Phase 3 | H23: S6-S10 | I23: recommendation + ai | J23: Architecture §3.10; AGENTS §2 | K23: POST /api/v1/recommendations/requirements | L23: ai_runs | M23: Requirement Extraction Agent, validate_requirements_schema, sanitize_untrusted_text | N23: SEQUENCE §3 | O23: Schema validation, ambiguous budget asks user, injection ignored
A24: V1 | B24: US-022 | C24: Apply hard constraints before ranking | D24: Consumer | E24: Must Have | F24: Draft | G24: Phase 3 | H24: S6-S10 | I24: recommendation | J24: Architecture §3.10 rules 1, 3 | K24: POST /api/v1/recommendations | L24: recommendations | M24: apply_hard_constraints, suggest_constraint_relaxation | N24: SEQUENCE §3 | O24: Over-budget 9.2-scored product is excluded; empty result gives relaxation hint
A25: V1 | B25: US-023 | C25: Personalized recommendations with explanation | D25: Consumer | E25: Must Have | F25: Draft | G25: Phase 3 | H25: S6-S10 | I25: recommendation + ai | J25: Architecture §3.10; AGENTS §8 | K25: POST /api/v1/recommendations | L25: recommendations, ai_runs | M25: rank_candidates, Recommendation Explanation Agent, validate_grounding, emit_event | N25: SEQUENCE §3 | O25: Determinism of ranking; explanation cites only ranking fields | P25: Ranking factors are heuristics
A26: V1 | B26: US-007 | C26: Save products | D26: Consumer | E26: Should Have | F26: Draft | G26: Phase 3 | H26: S6-S10 | I26: user_space | J26: DATA_MODEL §1.8 | K26: GET /api/v1/saved-products POST /api/v1/saved-products DELETE /api/v1/saved-products/{saved_id} | L26: saved_products | M26: emit_event | N26: - | O26: Integration + RLS: user cannot read another user's saved list
A27: V1 | B27: US-012 | C27: AI explanation of an evaluation | D27: Consumer | E27: Should Have | F27: Draft | G27: Phase 3 | H27: S6-S10 | I27: ai | J27: Architecture §3.13; AGENTS §6 | K27: POST /api/v1/evaluations/{evaluation_id}/explanation | L27: ai_runs | M27: Evaluation Explanation Agent, validate_grounding, sanitize_untrusted_text | N27: - | O27: AI contract tests: grounding, injection, empty input, template fallback
A28: V1 | B28: US-019 | C28: AI comparison summary | D28: Consumer | E28: Should Have | F28: Draft | G28: Phase 3 | H28: S6-S10 | I28: ai | J28: AGENTS §7 | K28: POST /api/v1/comparisons | L28: ai_runs | M28: Comparison Summary Agent, validate_grounding | N28: - | O28: AI contract: only comparison payload data; no blended verdict | P28: Summary is the `summary` field of the comparison response
A29: V1 | B29: US-024 | C29: Manage my preferences | D29: Consumer | E29: Should Have | F29: Draft | G29: Phase 3 | H29: S6-S10 | I29: user_space | J29: DATA_MODEL §1.8 | K29: GET /api/v1/preferences PUT /api/v1/preferences | L29: user_preferences | M29: - | N29: - | O29: Validation + privacy (own data only)
A30: V1 | B30: US-014 | C30: Submit structured feedback | D30: Public Reviewer | E30: Must Have | F30: Draft | G30: Phase 4 | H30: S9-S12 | I30: community | J30: Architecture §3.8 | K30: POST /api/v1/variants/{variant_id}/feedback | L30: feedback | M30: rate_limit_check | N30: - | O30: Integration: guest blocked, pending-until-moderated, own-edit only
A31: V1 | B31: US-015 | C31: View community insights | D31: Consumer | E31: Must Have | F31: Draft | G31: Phase 4 | H31: S9-S12 | I31: community + ai | J31: Architecture §3.8; AGENTS §5 | K31: GET /api/v1/variants/{variant_id}/community | L31: review_analysis, feedback | M31: Feedback Intelligence Agent | N31: - | O31: AI contract: every theme cites feedback_ids; community never changes the score
A32: V1 | B32: US-017 | C32: Moderate community feedback | D32: Admin | E32: Must Have | F32: Draft | G32: Phase 4 | H32: S9-S12 | I32: admin + community | J32: Architecture §3.8, §3.17 | K32: GET /api/v1/admin/moderation/queue POST /api/v1/admin/feedback/{feedback_id}/moderate | L32: moderation_actions, audit_log | M32: log_trace, emit_event | N32: - | O32: Role test: non-admin denied; audit row per decision
A33: V1 | B33: US-025 | C33: View current offers | D33: Consumer | E33: Must Have | F33: Clarification Required | G33: Phase 4 | H33: S9-S12 | I33: pricing + adapters | J33: Architecture §3.12 | K33: GET /api/v1/variants/{variant_id}/offers | L33: offers, listings | M33: compute_freshness | N33: SEQUENCE §6 | O33: Stale-offer flag; permitted sources only (adapter fixtures) | P33: Needs decision #1 and data-licensing answer
A34: V1 | B34: US-016 | C34: Review-quality signals | D34: Consumer | E34: Should Have | F34: Draft | G34: Phase 4 | H34: S9-S12 | I34: community | J34: Architecture §3.8 | K34: GET /api/v1/variants/{variant_id}/community | L34: review_quality_signals | M34: detect_near_duplicates, detect_review_bursts, build_review_quality_signals | N34: - | O34: Fixtures: burst of near-identical reviews flags; one harsh review does not; UI never says 'fake'
A35: V1 | B35: US-026 | C35: View price history | D35: Consumer | E35: Should Have | F35: Clarification Required | G35: Phase 4 | H35: S9-S12 | I35: pricing | J35: Architecture §3.12 | K35: GET /api/v1/variants/{variant_id}/price-history | L35: price_records | M35: get_price_context, record_price_observation | N35: SEQUENCE §6 | O35: Coverage reported; no forecast returned | P35: Depends on permitted price data
A36: V1 | B36: US-027 | C36: Create price and target-price alerts | D36: Consumer | E36: Should Have | F36: Draft | G36: Phase 4 | H36: S9-S12 | I36: pricing + notifications | J36: Architecture §3.12, §3.15 | K36: GET /api/v1/price-alerts POST /api/v1/price-alerts DELETE /api/v1/price-alerts/{alert_id} | L36: price_alerts, notifications | M36: evaluate_price_alert, record_price_observation | N36: SEQUENCE §6 | O36: Cooldown and oscillation tests; alert off switch
A37: V1 | B37: US-028 | C37: Control notification types | D37: Consumer | E37: Should Have | F37: Draft | G37: Phase 4 | H37: S9-S12 | I37: user_space + notifications | J37: Architecture §3.15 | K37: GET /api/v1/notification-settings PUT /api/v1/notification-settings | L37: notification_settings, notifications | M37: - | N37: - | O37: Disabled channel sends nothing; throttling/grouping
A38: V1 | B38: US-029 | C38: Create investigation case from potential issue | D38: Admin | E38: Should Have | F38: Clarification Required | G38: Phase 4 | H38: S9-S12 | I38: expert + admin | J38: Architecture §3.9 | K38: POST /api/v1/expert-cases | L38: expert_cases, audit_log | M38: log_trace | N38: SEQUENCE §4 | O38: Workflow tests; duplicate-case warning | P38: Expert workflow V1 vs V2 (decision #3)
A39: V1 | B39: US-030 | C39: Assign expert with conflict-of-interest check | D39: Admin | E39: Should Have | F39: Clarification Required | G39: Phase 4 | H39: S9-S12 | I39: expert + admin | J39: Architecture §3.9 | K39: POST /api/v1/expert-cases/{case_id}/assign | L39: experts, expert_assignments, coi_declarations | M39: check_permission | N39: SEQUENCE §4 | O39: Conflict blocks assignment; decline returns case to pool | P39: Decision #3
A40: V1 | B40: US-031 | C40: Submit expert assessment with proof | D40: Expert Reviewer | E40: Should Have | F40: Clarification Required | G40: Phase 4 | H40: S9-S12 | I40: expert + evidence | J40: Architecture §3.9 | K40: POST /api/v1/expert-cases/{case_id}/assessments | L40: expert_assessments, evidence_documents | M40: check_upload_safety | N40: SEQUENCE §4 | O40: Own-case only; malicious upload rejected; cannot change a published score | P40: Decision #3
A41: V1 | B41: US-032 | C41: Quality review and publish expert assessment | D41: Admin | E41: Should Have | F41: Clarification Required | G41: Phase 4 | H41: S9-S12 | I41: expert + evaluation | J41: Architecture §3.9 | K41: POST /api/v1/expert-assessments/{assessment_id}/review | L41: expert_assessments, evidence_versions, evaluations | M41: attach_trust_tier, aggregate_evaluation, emit_event | N41: SEQUENCE §4 | O41: Author cannot approve; approval creates tier-1 evidence and a new evaluation row | P41: Decision #3
...

Sheet Coverage
A1: Coverage summary (formulas over the Traceability sheet)
A3: Stories by phase and priority
A4: Phase | B4: Must | C4: Should | D4: Could | E4: Total
A5: Phase 1 | B5: =COUNTIFS(Traceability!$G$5:$G$57,$A5,Traceability!$E$5:$E$57,"Must Have") -> 9 | C5: =COUNTIFS(Traceability!$G$5:$G$57,$A5,Traceability!$E$5:$E$57,"Should Have") -> 0 | D5: =COUNTIFS(Traceability!$G$5:$G$57,$A5,Traceability!$E$5:$E$57,"Could Have") -> 0 | E5: =SUM(B5:D5) -> 9
A6: Phase 2 | B6: =COUNTIFS(Traceability!$G$5:$G$57,$A6,Traceability!$E$5:$E$57,"Must Have") -> 5 | C6: =COUNTIFS(Traceability!$G$5:$G$57,$A6,Traceability!$E$5:$E$57,"Should Have") -> 1 | D6: =COUNTIFS(Traceability!$G$5:$G$57,$A6,Traceability!$E$5:$E$57,"Could Have") -> 0 | E6: =SUM(B6:D6) -> 6
A7: Phase 3 | B7: =COUNTIFS(Traceability!$G$5:$G$57,$A7,Traceability!$E$5:$E$57,"Must Have") -> 6 | C7: =COUNTIFS(Traceability!$G$5:$G$57,$A7,Traceability!$E$5:$E$57,"Should Have") -> 4 | D7: =COUNTIFS(Traceability!$G$5:$G$57,$A7,Traceability!$E$5:$E$57,"Could Have") -> 0 | E7: =SUM(B7:D7) -> 10
A8: Phase 4 | B8: =COUNTIFS(Traceability!$G$5:$G$57,$A8,Traceability!$E$5:$E$57,"Must Have") -> 4 | C8: =COUNTIFS(Traceability!$G$5:$G$57,$A8,Traceability!$E$5:$E$57,"Should Have") -> 9 | D8: =COUNTIFS(Traceability!$G$5:$G$57,$A8,Traceability!$E$5:$E$57,"Could Have") -> 0 | E8: =SUM(B8:D8) -> 13
A9: Phase 5 | B9: =COUNTIFS(Traceability!$G$5:$G$57,$A9,Traceability!$E$5:$E$57,"Must Have") -> 2 | C9: =COUNTIFS(Traceability!$G$5:$G$57,$A9,Traceability!$E$5:$E$57,"Should Have") -> 1 | D9: =COUNTIFS(Traceability!$G$5:$G$57,$A9,Traceability!$E$5:$E$57,"Could Have") -> 0 | E9: =SUM(B9:D9) -> 3
A10: V2 | B10: =COUNTIFS(Traceability!$G$5:$G$57,$A10,Traceability!$E$5:$E$57,"Must Have") -> 0 | C10: =COUNTIFS(Traceability!$G$5:$G$57,$A10,Traceability!$E$5:$E$57,"Should Have") -> 4 | D10: =COUNTIFS(Traceability!$G$5:$G$57,$A10,Traceability!$E$5:$E$57,"Could Have") -> 4 | E10: =SUM(B10:D10) -> 8
A11: V3 | B11: =COUNTIFS(Traceability!$G$5:$G$57,$A11,Traceability!$E$5:$E$57,"Must Have") -> 0 | C11: =COUNTIFS(Traceability!$G$5:$G$57,$A11,Traceability!$E$5:$E$57,"Should Have") -> 0 | D11: =COUNTIFS(Traceability!$G$5:$G$57,$A11,Traceability!$E$5:$E$57,"Could Have") -> 4 | E11: =SUM(B11:D11) -> 4
A12: Total | B12: =SUM(B5:B11) -> 26 | C12: =SUM(C5:C11) -> 19 | D12: =SUM(D5:D11) -> 8 | E12: =SUM(E5:E11) -> 53
A14: Stories by status
A15: Status | B15: Count
A16: Draft | B16: =COUNTIF(Traceability!$F$5:$F$57,$A16) -> 40
A17: Clarification Required | B17: =COUNTIF(Traceability!$F$5:$F$57,$A17) -> 13
A18: Ready for Development | B18: =COUNTIF(Traceability!$F$5:$F$57,$A18) -> 0
A19: In Development | B19: =COUNTIF(Traceability!$F$5:$F$57,$A19) -> 0
A20: Ready for QA | B20: =COUNTIF(Traceability!$F$5:$F$57,$A20) -> 0
A21: Done | B21: =COUNTIF(Traceability!$F$5:$F$57,$A21) -> 0
A22: Blocked | B22: =COUNTIF(Traceability!$F$5:$F$57,$A22) -> 0
A23: Total | B23: =SUM(B16:B22) -> 53
A25: Mapping completeness checks
A26: Check | B26: Value
A27: Stories mapped | B27: =COUNTA(Traceability!$B$5:$B$57) -> 53
A28: Stories with endpoints in the API skeleton | B28: =COUNTIF(Traceability!$K$5:$K$57,"*/api/v1/*")+COUNTIF(Traceability!$K$5:$K$57,"*/healthz*") -> 44
A29: Stories whose endpoint is planned (not yet specified) | B29: =COUNTIF(Traceability!$K$5:$K$57,"Planned*") -> 7
A30: Stories reusing V1 endpoints | B30: =COUNTIF(Traceability!$K$5:$K$57,"Reuses*") -> 1
A31: Negative requirements (no endpoint) | B31: =COUNTIF(Traceability!$K$5:$K$57,"None*") -> 1
A32: Check: categories add up to stories mapped | B32: =IF(B27=B28+B29+B30+B31,"OK","MISMATCH") -> OK
A34: Source: story data from Review_Master_User_Stories.xlsx; mapping built from the architecture package. Phase and sprint columns come from DELIVERY_PLAN.md.

Sheet Endpoint index
A1: API endpoint -> stories (generated from the mapping at build time)
A3: Method | B3: Path | C3: Stories | D3: Note
A4: GET | B4: /api/v1/admin/audit-log | C4: US-037
A5: POST | B5: /api/v1/admin/evaluation-model-versions/{version_id}/publish | C5: US-034
A6: GET | B6: /api/v1/admin/evaluation-models | C6: US-034
A7: POST | B7: /api/v1/admin/evaluation-models | C7: US-053
A8: GET | B8: /api/v1/admin/evaluation-models/{model_id} | C8: US-034
A9: POST | B9: /api/v1/admin/evaluation-models/{model_id}/versions | C9: US-034
A10: POST | B10: /api/v1/admin/feedback/{feedback_id}/moderate | C10: US-017
A11: GET | B11: /api/v1/admin/integrations | C11: US-038
A12: GET | B12: /api/v1/admin/mappings/queue | C12: US-035
A13: POST | B13: /api/v1/admin/mappings/{item_id}/resolve | C13: US-035
A14: GET | B14: /api/v1/admin/moderation/queue | C14: US-017
A15: GET | B15: /api/v1/admin/users | C15: US-033
... A19: DELETE | B19: /api/v1/api-keys/{key_id} | C19: US-040
A20: POST | B20: /api/v1/auth/login | C20: - | D20: Sign-up/login/session: no explicit user story (see gap G1)
A21: POST | B21: /api/v1/auth/logout | C21: - | D21: Sign-up/login/session: no explicit user story (see gap G1)
A22: POST | B22: /api/v1/auth/refresh | C22: - | D22: Sign-up/login/session: no explicit user story (see gap G1)
A23: POST | B23: /api/v1/auth/signup | C23: - | D23: Sign-up/login/session: no explicit user story (see gap G1)
A24: POST | B24: /api/v1/auth/verify-email | C24: - | D24: Sign-up/login/session: no explicit user story (see gap G1)
A25: POST | B25: /api/v1/chat/messages | C25: US-042
A26: POST | B26: /api/v1/comparisons | C26: US-018, US-019
A27: POST | B27: /api/v1/evaluations/{evaluation_id}/explanation | C27: US-012
A28: POST | B28: /api/v1/evidence | C28: US-036, US-049
A29: GET | B29: /api/v1/evidence/{evidence_id} | C29: US-011
A30: GET | B30: /api/v1/evidence/{evidence_id}/versions | C30: US-011
A31: POST | B31: /api/v1/evidence/{evidence_id}/versions | C31: US-036
A32: POST | B32: /api/v1/expert-assessments/{assessment_id}/review | C32: US-032
A33: POST | B33: /api/v1/expert-cases | C33: US-029
A34: POST | B34: /api/v1/expert-cases/{case_id}/assessments | C34: US-031
A35: POST | B35: /api/v1/expert-cases/{case_id}/assign | C35: US-030
A36: GET | B36: /api/v1/notification-settings | C36: US-028
... A65: POST | B65: /api/v1/webhooks/{webhook_id}/deliveries/{delivery_id}/replay | C65: US-041
A66: GET | B66: /healthz | C66: - | D66: Platform operation (probes), no user story
A67: GET | B67: /readyz | C67: - | D67: Platform operation (probes), no user story
